[2023-07-21 18:20:35,700] {taskinstance.py:1159} INFO - Dependencies all met for <TaskInstance: dag_digitalskola_finalproject.insert_data_to_dim_province manual__2023-07-21T18:20:09.882685+00:00 [queued]>
[2023-07-21 18:20:36,069] {taskinstance.py:1159} INFO - Dependencies all met for <TaskInstance: dag_digitalskola_finalproject.insert_data_to_dim_province manual__2023-07-21T18:20:09.882685+00:00 [queued]>
[2023-07-21 18:20:36,089] {taskinstance.py:1356} INFO - 
--------------------------------------------------------------------------------
[2023-07-21 18:20:36,204] {taskinstance.py:1357} INFO - Starting attempt 1 of 1
[2023-07-21 18:20:36,207] {taskinstance.py:1358} INFO - 
--------------------------------------------------------------------------------
[2023-07-21 18:20:36,339] {taskinstance.py:1377} INFO - Executing <Task(PythonOperator): insert_data_to_dim_province> on 2023-07-21 18:20:09.882685+00:00
[2023-07-21 18:20:36,394] {standard_task_runner.py:52} INFO - Started process 1958 to run task
[2023-07-21 18:20:36,403] {standard_task_runner.py:79} INFO - Running: ['***', 'tasks', 'run', 'dag_digitalskola_finalproject', 'insert_data_to_dim_province', 'manual__2023-07-21T18:20:09.882685+00:00', '--job-id', '16', '--raw', '--subdir', 'DAGS_FOLDER/dag_digitalskola_finalproject.py', '--cfg-path', '/tmp/tmpwem6hccm', '--error-file', '/tmp/tmp6k0_rxep']
[2023-07-21 18:20:36,418] {standard_task_runner.py:80} INFO - Job 16: Subtask insert_data_to_dim_province
[2023-07-21 18:20:37,177] {task_command.py:369} INFO - Running <TaskInstance: dag_digitalskola_finalproject.insert_data_to_dim_province manual__2023-07-21T18:20:09.882685+00:00 [running]> on host 34be34978432
[2023-07-21 18:20:38,040] {taskinstance.py:1571} INFO - Exporting the following env vars:
AIRFLOW_CTX_DAG_OWNER=***
AIRFLOW_CTX_DAG_ID=dag_digitalskola_finalproject
AIRFLOW_CTX_TASK_ID=insert_data_to_dim_province
AIRFLOW_CTX_EXECUTION_DATE=2023-07-21T18:20:09.882685+00:00
AIRFLOW_CTX_TRY_NUMBER=1
AIRFLOW_CTX_DAG_RUN_ID=manual__2023-07-21T18:20:09.882685+00:00
[2023-07-21 18:20:38,965] {transformer.py:13} INFO - GET DATA FROM covid_jabar SUCCESS
[2023-07-21 18:20:38,978] {taskinstance.py:1889} ERROR - Task failed with exception
Traceback (most recent call last):
  File "/home/airflow/.local/lib/python3.7/site-packages/airflow/operators/python.py", line 171, in execute
    return_value = self.execute_callable()
  File "/home/airflow/.local/lib/python3.7/site-packages/airflow/operators/python.py", line 189, in execute_callable
    return self.python_callable(*self.op_args, **self.op_kwargs)
  File "/opt/airflow/dags/dag_digitalskola_finalproject.py", line 48, in insert_data_to_dim_province
    transformer.insert_data_to_dim_province()
  File "/opt/airflow/dags/modules/transformer.py", line 18, in insert_data_to_dim_province
    df_province = df_covidjabar[['kode_prov','name_prov']]
  File "/home/airflow/.local/lib/python3.7/site-packages/pandas/core/frame.py", line 3464, in __getitem__
    indexer = self.loc._get_listlike_indexer(key, axis=1)[1]
  File "/home/airflow/.local/lib/python3.7/site-packages/pandas/core/indexing.py", line 1314, in _get_listlike_indexer
    self._validate_read_indexer(keyarr, indexer, axis)
  File "/home/airflow/.local/lib/python3.7/site-packages/pandas/core/indexing.py", line 1377, in _validate_read_indexer
    raise KeyError(f"{not_found} not in index")
KeyError: "['name_prov'] not in index"
[2023-07-21 18:20:39,088] {taskinstance.py:1400} INFO - Marking task as FAILED. dag_id=dag_digitalskola_finalproject, task_id=insert_data_to_dim_province, execution_date=20230721T182009, start_date=20230721T182035, end_date=20230721T182039
[2023-07-21 18:20:39,189] {standard_task_runner.py:97} ERROR - Failed to execute job 16 for task insert_data_to_dim_province ("['name_prov'] not in index"; 1958)
[2023-07-21 18:20:39,241] {local_task_job.py:156} INFO - Task exited with return code 1
[2023-07-21 18:20:39,504] {local_task_job.py:273} INFO - 0 downstream tasks scheduled from follow-on schedule check
